Workbook

Sheet Setup
A1: La Cata – Control Total (LMF + DF + SJM)
A2: Concepto | B2: Valor | D2: Notas | G2: Ubicaciones
A3: Ubicación 1 | B3: La Cata LMF | D3: Color: Azul | G3: La Cata LMF
A4: Ubicación 2 | B4: La Cata DF | D4: Color: Verde | G4: La Cata DF
A5: Ubicación 3 | B5: La Cata SJM | D5: Color: Naranja | G5: La Cata SJM
A6: Fee Tarjeta | B6: 0.0345 | D6: 3.45% comisión bancaria | G6: AMBAS
A7: ITBIS % | B7: 0.18 | D7: Solo ventas gravadas (no alcohol)
A8: % Empresa | B8: 0.5 | D8: Distribución utilidades
A9: % Socio A | B9: 0.25 | D9: Distribución utilidades
A10: % Socio B | B10: 0.25 | D10: Distribución utilidades

Sheet Ventas Diarias
A1: FECHA | B1: UBICACION | C1: EFECTIVO | D1: TARJETA (BRUTA) | E1: FEE TARJETA (3.45%) | F1: TARJETA NETA | G1: TRANSFERENCIAS | H1: PEDIDOS YA | I1: NOTAS DE CREDITO (-) | J1: TOTAL COBRADO CON ITBS | K1: VENTAS GRABADAS (BASE SIN ITBS) | L1: ITBS COBRADO | M1: VENTAS SIN ITBIS (para utilidad) | N1: DEPOSITO EFECTIVO (SEMANAL) | O1: NOTAS
A2: 46023 | B2: La Cata LMF | C2: 561911.56 | D2: 191788.96 | E2: =D2*Setup!$B$6 | F2: =D2-E2 | G2: 0 | I2: 705 | J2: =C2+F2+G2-I2 | L2: =K2*Setup!$B$7 | M2: =J2-L2
A3: 46023 | B3: La Cata DF | C3: 16502.6 | D3: 15265 | E3: =D3*Setup!$B$6 | F3: =D3-E3 | G3: 0 | I3: 0 | J3: =C3+F3+G3-I3 | L3: =K3*Setup!$B$7 | M3: =J3-L3
A4: 46024 | B4: La Cata LMF | C4: 243603 | D4: 126392 | E4: =D4*Setup!$B$6 | F4: =D4-E4 | G4: 7890 | I4: 395 | J4: =C4+F4+G4-I4 | L4: =K4*Setup!$B$7 | M4: =J4-L4
A5: 46024 | B5: La Cata DF | C5: 3875 | D5: 2080 | E5: =D5*Setup!$B$6 | F5: =D5-E5 | G5: 0 | I5: 0 | J5: =C5+F5+G5-I5 | L5: =K5*Setup!$B$7 | M5: =J5-L5
A6: 46025 | B6: La Cata LMF | C6: 111795.61 | D6: 114720 | E6: =D6*Setup!$B$6 | F6: =D6-E6 | G6: 16502 | I6: 6219 | J6: =C6+F6+G6-I6 | L6: =K6*Setup!$B$7 | M6: =J6-L6
A7: 46025 | B7: La Cata DF | C7: 6495 | D7: 2695 | E7: =D7*Setup!$B$6 | F7: =D7-E7 | G7: 0 | I7: 0 | J7: =C7+F7+G7-I7 | L7: =K7*Setup!$B$7 | M7: =J7-L7
A8: 46026 | B8: La Cata LMF | C8: 150879 | D8: 94242 | E8: =D8*Setup!$B$6 | F8: =D8-E8 | G8: 2865 | I8: 0 | J8: =C8+F8+G8-I8 | L8: =K8*Setup!$B$7 | M8: =J8-L8
A9: 46026 | B9: La Cata DF | C9: 17995 | D9: 9272.6 | E9: =D9*Setup!$B$6 | F9: =D9-E9 | G9: 0 | I9: 0 | J9: =C9+F9+G9-I9 | L9: =K9*Setup!$B$7 | M9: =J9-L9
A10: 46027 | B10: La Cata LMF | C10: 54994 | D10: 22455 | E10: =D10*Setup!$B$6 | F10: =D10-E10 | G10: 645 | I10: 220 | J10: =C10+F10+G10-I10 | L10: =K10*Setup!$B$7 | M10: =J10-L10
A11: 46027 | B11: La Cata DF | C11: 6355 | D11: 650 | E11: =D11*Setup!$B$6 | F11: =D11-E11 | G11: 0 | I11: 0 | J11: =C11+F11+G11-I11 | L11: =K11*Setup!$B$7 | M11: =J11-L11
A12: 46028 | B12: La Cata LMF | C12: 45555 | D12: 13990 | E12: =D12*Setup!$B$6 | F12: =D12-E12 | G12: 1190 | I12: 0 | J12: =C12+F12+G12-I12 | L12: =K12*Setup!$B$7 | M12: =J12-L12 | N12: 511590
A13: 46028 | B13: La Cata DF | C13: 6055 | D13: 395 | E13: =D13*Setup!$B$6 | F13: =D13-E13 | G13: 0 | I13: 0 | J13: =C13+F13+G13-I13 | L13: =K13*Setup!$B$7 | M13: =J13-L13
A14: 46029 | B14: La Cata LMF | C14: 50380 | D14: 9300 | E14: =D14*Setup!$B$6 | F14: =D14-E14 | G14: 195 | I14: 0 | J14: =C14+F14+G14-I14 | L14: =K14*Setup!$B$7 | M14: =J14-L14
A15: 46029 | B15: La Cata DF | C15: 8160 | D15: 390 | E15: =D15*Setup!$B$6 | F15: =D15-E15 | G15: 0 | I15: 0 | J15: =C15+F15+G15-I15 | L15: =K15*Setup!$B$7 | M15: =J15-L15
A16: 46030 | B16: La Cata LMF | C16: 37165 | D16: 3720 | E16: =D16*Setup!$B$6 | F16: =D16-E16 | G16: 0 | I16: 0 | J16: =C16+F16+G16-I16 | L16: =K16*Setup!$B$7 | M16: =J16-L16
A17: 46030 | B17: La Cata DF | C17: 8080 | D17: 1485 | E17: =D17*Setup!$B$6 | F17: =D17-E17 | G17: 0 | I17: 0 | J17: =C17+F17+G17-I17 | L17: =K17*Setup!$B$7 | M17: =J17-L17
A18: 46031 | B18: La Cata LMF | C18: 34940 | D18: 34250 | E18: =D18*Setup!$B$6 | F18: =D18-E18 | G18: 1930 | I18: 0 | J18: =C18+F18+G18-I18 | L18: =K18*Setup!$B$7 | M18: =J18-L18
A19: 46031 | B19: La Cata DF | C19: 4805 | D19: 3050 | E19: =D19*Setup!$B$6 | F19: =D19-E19 | G19: 0 | I19: 0 | J19: =C19+F19+G19-I19 | L19: =K19*Setup!$B$7 | M19: =J19-L19
A20: 46032 | B20: La Cata LMF | C20: 78191 | D20: 28095 | E20: =D20*Setup!$B$6 | F20: =D20-E20 | G20: 0 | I20: 995 | J20: =C20+F20+G20-I20 | L20: =K20*Setup!$B$7 | M20: =J20-L20
A21: 46032 | B21: La Cata DF | C21: 16570 | D21: 11145 | E21: =D21*Setup!$B$6 | F21: =D21-E21 | G21: 0 | I21: 0 | J21: =C21+F21+G21-I21 | L21: =K21*Setup!$B$7 | M21: =J21-L21
A22: 46033 | B22: La Cata LMF | C22: 103865 | D22: 48035 | E22: =D22*Setup!$B$6 | F22: =D22-E22 | G22: 2325 | I22: 0 | J22: =C22+F22+G22-I22 | L22: =K22*Setup!$B$7 | M22: =J22-L22
A23: 46033 | B23: La Cata DF | C23: 9370 | D23: 4005 | E23: =D23*Setup!$B$6 | F23: =D23-E23 | G23: 0 | I23: 0 | J23: =C23+F23+G23-I23 | L23: =K23*Setup!$B$7 | M23: =J23-L23
A24: 46034 | B24: La Cata LMF | C24: 24400 | D24: 14880 | E24: =D24*Setup!$B$6 | F24: =D24-E24 | G24: 0 | I24: 870 | J24: =C24+F24+G24-I24 | L24: =K24*Setup!$B$7 | M24: =J24-L24 | N24: 408130
A25: 46034 | B25: La Cata DF | C25: 5010 | D25: 0 | E25: =D25*Setup!$B$6 | F25: =D25-E25 | G25: 0 | I25: 0 | J25: =C25+F25+G25-I25 | L25: =K25*Setup!$B$7 | M25: =J25-L25
A26: 46035 | B26: La Cata LMF | C26: 42075 | D26: 12823 | E26: =D26*Setup!$B$6 | F26: =D26-E26 | G26: 1350 | I26: 675 | J26: =C26+F26+G26-I26 | L26: =K26*Setup!$B$7 | M26: =J26-L26
A27: 46035 | B27: La Cata DF | C27: 0 | D27: 0 | E27: =D27*Setup!$B$6 | F27: =D27-E27 | G27: 0 | I27: 0 | J27: =C27+F27+G27-I27 | L27: =K27*Setup!$B$7 | M27: =J27-L27
A28: 46036 | B28: La Cata LMF | C28: 39490 | D28: 3100 | E28: =D28*Setup!$B$6 | F28: =D28-E28 | G28: 5125 | I28: 0 | J28: =C28+F28+G28-I28 | L28: =K28*Setup!$B$7 | M28: =J28-L28
A29: 46036 | B29: La Cata DF | C29: 8985 | D29: 990 | E29: =D29*Setup!$B$6 | F29: =D29-E29 | G29: 0 | I29: 0 | J29: =C29+F29+G29-I29 | L29: =K29*Setup!$B$7 | M29: =J29-L29
A30: 46037 | B30: La Cata LMF | C30: 27070 | D30: 30350 | E30: =D30*Setup!$B$6 | F30: =D30-E30 | G30: 0 | I30: 0 | J30: =C30+F30+G30-I30 | L30: =K30*Setup!$B$7 | M30: =J30-L30
A31: 46037 | B31: La Cata DF | C31: 5020 | D31: 2515 | E31: =D31*Setup!$B$6 | F31: =D31-E31 | G31: 0 | I31: 0 | J31: =C31+F31+G31-I31 | L31: =K31*Setup!$B$7 | M31: =J31-L31
A32: 46038 | B32: La Cata LMF | C32: 42968 | D32: 35085 | E32: =D32*Setup!$B$6 | F32: =D32-E32 | G32: 0 | I32: 0 | J32: =C32+F32+G32-I32 | L32: =K32*Setup!$B$7 | M32: =J32-L32
A33: 46038 | B33: La Cata DF | C33: 15315 | D33: 5585 | E33: =D33*Setup!$B$6 | F33: =D33-E33 | G33: 9000 | I33: 0 | J33: =C33+F33+G33-I33 | L33: =K33*Setup!$B$7 | M33: =J33-L33
A34: 46039 | B34: La Cata LMF | C34: 109222 | D34: 55501 | E34: =D34*Setup!$B$6 | F34: =D34-E34 | G34: 420 | I34: 820 | J34: =C34+F34+G34-I34 | L34: =K34*Setup!$B$7 | M34: =J34-L34
A35: 46039 | B35: La Cata DF | C35: 17110 | D35: 13045 | E35: =D35*Setup!$B$6 | F35: =D35-E35 | G35: 0 | I35: 0 | J35: =C35+F35+G35-I35 | L35: =K35*Setup!$B$7 | M35: =J35-L35
A36: 46040 | B36: La Cata LMF | C36: 102670 | D36: 29893 | E36: =D36*Setup!$B$6 | F36: =D36-E36 | G36: 900 | I36: 0 | J36: =C36+F36+G36-I36 | L36: =K36*Setup!$B$7 | M36: =J36-L36
A37: 46040 | B37: La Cata DF | C37: 26885 | D37: 15085 | E37: =D37*Setup!$B$6 | F37: =D37-E37 | G37: 735 | I37: 0 | J37: =C37+F37+G37-I37 | L37: =K37*Setup!$B$7 | M37: =J37-L37
A38: 46041 | B38: La Cata LMF | C38: 28194 | D38: 6985 | E38: =D38*Setup!$B$6 | F38: =D38-E38 | G38: 0 | I38: 0 | J38: =C38+F38+G38-I38 | L38: =K38*Setup!$B$7 | M38: =J38-L38 | N38: 387540
A39: 46041 | B39: La Cata DF | C39: 4480 | D39: 1465 | E39: =D39*Setup!$B$6 | F39: =D39-E39 | G39: 0 | I39: 0 | J39: =C39+F39+G39-I39 | L39: =K39*Setup!$B$7 | M39: =J39-L39
A40: 46042 | B40: La Cata LMF | C40: 39706 | D40: 20212 | E40: =D40*Setup!$B$6 | F40: =D40-E40 | G40: 1450 | I40: 0 | J40: =C40+F40+G40-I40 | L40: =K40*Setup!$B$7 | M40: =J40-L40
...

Sheet Ventas Diarias Backup
A1: FECHA | B1: UBICACION | C1: EFECTIVO | D1: TARJETA (BRUTA) | E1: FEE TARJETA (3.45%) | F1: TARJETA NETA | G1: TRANSFERENCIAS | H1: PEDIDOS YA | I1: NOTAS DE CREDITO (-) | J1: TOTAL COBRADO CON ITBS | K1: VENTAS GRABADAS (BASE SIN ITBS) | L1: ITBS COBRADO | M1: VENTAS SIN ITBIS (para utilidad) | N1: DEPOSITO EFECTIVO (SEMANAL) | O1: NOTAS
A2: 46174 | B2: La Cata LMF | C2: 20725 | D2: 5905 | E2: =D2*Setup!$B$5 | F2: =D2-E2 | G2: 2365 | I2: 0 | J2: =C2+F2+G2-I2 | L2: =K2*Setup!$B$6 | M2: =J2-L2
A3: 46175 | B3: La Cata LMF | C3: 39077 | D3: 12420 | E3: =D3*Setup!$B$5 | F3: =D3-E3 | G3: 0 | I3: 0 | J3: =C3+F3+G3-I3 | L3: =K3*Setup!$B$6 | M3: =J3-L3
A4: 46176 | B4: La Cata LMF | C4: 54488 | D4: 13620 | E4: =D4*Setup!$B$5 | F4: =D4-E4 | G4: 1866 | I4: 0 | J4: =C4+F4+G4-I4 | L4: =K4*Setup!$B$6 | M4: =J4-L4
A5: 46177 | B5: La Cata LMF | C5: 104926 | D5: 46270 | E5: =D5*Setup!$B$5 | F5: =D5-E5 | G5: 3255 | I5: 0 | J5: =C5+F5+G5-I5 | L5: =K5*Setup!$B$6 | M5: =J5-L5
A6: 46178 | B6: La Cata LMF | C6: 0 | D6: 0 | E6: =D6*Setup!$B$5 | F6: =D6-E6 | G6: 0 | I6: 0 | J6: =C6+F6+G6-I6 | L6: =K6*Setup!$B$6 | M6: =J6-L6
A7: 46179 | B7: La Cata LMF | C7: 135910 | D7: 38305 | E7: =D7*Setup!$B$5 | F7: =D7-E7 | G7: 6875 | I7: 0 | J7: =C7+F7+G7-I7 | L7: =K7*Setup!$B$6 | M7: =J7-L7
A8: 46180 | B8: La Cata LMF | C8: 168335 | D8: 53835 | E8: =D8*Setup!$B$5 | F8: =D8-E8 | G8: 0 | I8: 0 | J8: =C8+F8+G8-I8 | L8: =K8*Setup!$B$6 | M8: =J8-L8
A9: 46181 | B9: La Cata LMF | C9: 20725 | D9: 5905 | E9: =D9*Setup!$B$5 | F9: =D9-E9 | G9: 2365 | I9: 0 | J9: =C9+F9+G9-I9 | L9: =K9*Setup!$B$6 | M9: =J9-L9 | N9: 623815
A10: 46182 | B10: La Cata LMF | C10: 33510 | D10: 11355 | E10: =D10*Setup!$B$5 | F10: =D10-E10 | G10: 0 | I10: 0 | J10: =C10+F10+G10-I10 | L10: =K10*Setup!$B$6 | M10: =J10-L10
A11: 46183 | B11: La Cata LMF | C11: 19035 | D11: 4460 | E11: =D11*Setup!$B$5 | F11: =D11-E11 | G11: 0 | I11: 0 | J11: =C11+F11+G11-I11 | L11: =K11*Setup!$B$6 | M11: =J11-L11
A12: 46184 | B12: La Cata LMF | C12: 14400 | D12: 9505 | E12: =D12*Setup!$B$5 | F12: =D12-E12 | G12: 0 | I12: 0 | J12: =C12+F12+G12-I12 | L12: =K12*Setup!$B$6 | M12: =J12-L12
A13: 46185 | B13: La Cata LMF | C13: 47335 | D13: 14035 | E13: =D13*Setup!$B$5 | F13: =D13-E13 | G13: 1290 | I13: 160 | J13: =C13+F13+G13-I13 | L13: =K13*Setup!$B$6 | M13: =J13-L13
A14: 46186 | B14: La Cata LMF | C14: 114934 | D14: 40440 | E14: =D14*Setup!$B$5 | F14: =D14-E14 | G14: 16775 | I14: 0 | J14: =C14+F14+G14-I14 | L14: =K14*Setup!$B$6 | M14: =J14-L14
A15: 46187 | B15: La Cata LMF | C15: 183535 | D15: 53845 | E15: =D15*Setup!$B$5 | F15: =D15-E15 | G15: 1740 | I15: 0 | J15: =C15+F15+G15-I15 | L15: =K15*Setup!$B$6 | M15: =J15-L15
A16: 46188 | B16: La Cata LMF | C16: 29567 | D16: 9435 | E16: =D16*Setup!$B$5 | F16: =D16-E16 | G16: 2765 | I16: 0 | J16: =C16+F16+G16-I16 | L16: =K16*Setup!$B$6 | M16: =J16-L16 | N16: 434840
A17: 46189 | B17: La Cata LMF | C17: 30559 | D17: 10346 | E17: =D17*Setup!$B$5 | F17: =D17-E17 | G17: 0 | I17: 0 | J17: =C17+F17+G17-I17 | L17: =K17*Setup!$B$6 | M17: =J17-L17
A18: 46190 | B18: La Cata LMF | C18: 37857 | D18: 27615 | E18: =D18*Setup!$B$5 | F18: =D18-E18 | G18: 0 | I18: 0 | J18: =C18+F18+G18-I18 | L18: =K18*Setup!$B$6 | M18: =J18-L18
A19: 46191 | B19: La Cata LMF | C19: 29700 | D19: 24095 | E19: =D19*Setup!$B$5 | F19: =D19-E19 | G19: 0 | I19: 0 | J19: =C19+F19+G19-I19 | L19: =K19*Setup!$B$6 | M19: =J19-L19
A20: 46192 | B20: La Cata LMF | C20: 65320 | D20: 37590 | E20: =D20*Setup!$B$5 | F20: =D20-E20 | G20: 420 | I20: 0 | J20: =C20+F20+G20-I20 | L20: =K20*Setup!$B$6 | M20: =J20-L20
A21: 46193 | B21: La Cata LMF | C21: 137440 | D21: 80635 | E21: =D21*Setup!$B$5 | F21: =D21-E21 | G21: 760 | I21: 0 | J21: =C21+F21+G21-I21 | L21: =K21*Setup!$B$6 | M21: =J21-L21
A22: 46194 | B22: La Cata LMF | C22: 151265 | D22: 65345 | E22: =D22*Setup!$B$5 | F22: =D22-E22 | G22: 3155 | I22: 0 | J22: =C22+F22+G22-I22 | L22: =K22*Setup!$B$6 | M22: =J22-L22
A23: 46195 | B23: La Cata LMF | C23: 24815 | D23: 16840 | E23: =D23*Setup!$B$5 | F23: =D23-E23 | G23: 600 | I23: 0 | J23: =C23+F23+G23-I23 | L23: =K23*Setup!$B$6 | M23: =J23-L23
A24: 46196 | B24: La Cata LMF | C24: 55010 | D24: 15505 | E24: =D24*Setup!$B$5 | F24: =D24-E24 | G24: 2660 | I24: 0 | J24: =C24+F24+G24-I24 | L24: =K24*Setup!$B$6 | M24: =J24-L24
A25: 46197 | B25: La Cata LMF | C25: 59190 | D25: 25428 | E25: =D25*Setup!$B$5 | F25: =D25-E25 | G25: 80 | I25: 0 | J25: =C25+F25+G25-I25 | L25: =K25*Setup!$B$6 | M25: =J25-L25
A26: 46198 | B26: La Cata LMF | C26: 54185 | D26: 25635 | E26: =D26*Setup!$B$5 | F26: =D26-E26 | G26: 1925 | I26: 0 | J26: =C26+F26+G26-I26 | L26: =K26*Setup!$B$6 | M26: =J26-L26
A27: 46199 | B27: La Cata LMF | C27: 46815 | D27: 32320 | E27: =D27*Setup!$B$5 | F27: =D27-E27 | G27: 375 | I27: 0 | J27: =C27+F27+G27-I27 | L27: =K27*Setup!$B$6 | M27: =J27-L27
A28: 46200 | B28: La Cata LMF | C28: 160930 | D28: 69930 | E28: =D28*Setup!$B$5 | F28: =D28-E28 | G28: 3160 | I28: 4585 | J28: =C28+F28+G28-I28 | L28: =K28*Setup!$B$6 | M28: =J28-L28
... A32: 46174 | B32: La Cata DF | C32: 4460 | D32: 3305 | E32: =D32*Setup!$B$5 | F32: =D32-E32 | G32: 0 | I32: 0 | J32: =C32+F32+G32-I32 | L32: =K32*Setup!$B$6 | M32: =J32-L32
A33: 46175 | B33: La Cata DF | E33: =D33*Setup!$B$5 | F33: =D33-E33 | G33: 0 | I33: 0 | J33: =C33+F33+G33-I33 | L33: =K33*Setup!$B$6 | M33: =J33-L33
A34: 46176 | B34: La Cata DF | E34: =D34*Setup!$B$5 | F34: =D34-E34 | G34: 0 | I34: 0 | J34: =C34+F34+G34-I34 | L34: =K34*Setup!$B$6 | M34: =J34-L34
A35: 46177 | B35: La Cata DF | E35: =D35*Setup!$B$5 | F35: =D35-E35 | G35: 0 | I35: 0 | J35: =C35+F35+G35-I35 | L35: =K35*Setup!$B$6 | M35: =J35-L35
A36: 46178 | B36: La Cata DF | E36: =D36*Setup!$B$5 | F36: =D36-E36 | G36: 0 | I36: 0 | J36: =C36+F36+G36-I36 | L36: =K36*Setup!$B$6 | M36: =J36-L36
A37: 46179 | B37: La Cata DF | E37: =D37*Setup!$B$5 | F37: =D37-E37 | G37: 0 | I37: 0 | J37: =C37+F37+G37-I37 | L37: =K37*Setup!$B$6 | M37: =J37-L37
A38: 46180 | B38: La Cata DF | E38: =D38*Setup!$B$5 | F38: =D38-E38 | G38: 0 | I38: 0 | J38: =C38+F38+G38-I38 | L38: =K38*Setup!$B$6 | M38: =J38-L38
A39: 46181 | B39: La Cata DF | E39: =D39*Setup!$B$5 | F39: =D39-E39 | G39: 0 | I39: 0 | J39: =C39+F39+G39-I39 | L39: =K39*Setup!$B$6 | M39: =J39-L39
A40: 46182 | B40: La Cata DF | E40: =D40*Setup!$B$5 | F40: =D40-E40 | G40: 0 | I40: 0 | J40: =C40+F40+G40-I40 | L40: =K40*Setup!$B$6 | M40: =J40-L40 | N40: 181328
A41: 46183 | B41: La Cata DF | E41: =D41*Setup!$B$5 | F41: =D41-E41 | G41: 0 | I41: 0 | J41: =C41+F41+G41-I41 | L41: =K41*Setup!$B$6 | M41: =J41-L41
A42: 46184 | B42: La Cata DF | E42: =D42*Setup!$B$5 | F42: =D42-E42 | G42: 0 | I42: 0 | J42: =C42+F42+G42-I42 | L42: =K42*Setup!$B$6 | M42: =J42-L42
A43: 46185 | B43: La Cata DF | E43: =D43*Setup!$B$5 | F43: =D43-E43 | G43: 0 | I43: 0 | J43: =C43+F43+G43-I43 | L43: =K43*Setup!$B$6 | M43: =J43-L43
...

Sheet Gastos
A1: FECHA | B1: UBICACION | C1: CATEGORIA | D1: SUBCATEGORIA | E1: MONTO | F1: METODO PAGO | G1: ESTADO | H1: NOTAS
A2: 46028 | B2: La Cata LMF | C2: Gastos Fijos | D2: Internet | E2: 9000 | F2: Transferencia | G2: Pago | H2: Pago Ignacio
A3: 46029 | B3: La Cata LMF | C3: Operación | D3: Caja chica | E3: 5000 | F3: Transferencia | G3: Pago
A4: 46031 | B4: La Cata DF | C4: Operación | D4: Trabajo | E4: 2500 | F4: Transferencia | G4: Pago | H4: Instalacion Camara
A5: 46034 | B5: La Cata LMF | C5: Operación | D5: Caja chica | E5: 5000 | F5: Transferencia | G5: Pago
A6: 46036 | B6: La Cata LMF | C6: Operación | D6: Electricidad | E6: 49776.58 | F6: Transferencia | G6: Pago | H6: Ambas Sucursales
A7: 46036 | B7: La Cata LMF | C7: Operación | D7: Nomina | E7: 56500 | F7: Transferencia | G7: Pago | H7: Ambas Sucursales
A8: 46037 | B8: La Cata LMF | C8: Operación | D8: Nomina | E8: 5000 | F8: Transferencia | G8: Pago | H8: Pago Contable LMF
A9: 46042 | B9: La Cata DF | C9: Operación | D9: Trabajo | E9: 900 | F9: Transferencia | G9: Pago | H9: Trabajo electrico: Henry Troncoso
A10: 46042 | B10: La Cata DF | C10: Administrativos | D10: Motor DF | E10: 50000 | F10: Transferencia | G10: Pago | H10: Pago a Chobelo
A11: 46050 | B11: La Cata DF | C11: Gastos Fijos | D11: Renta | E11: 29000 | F11: Transferencia | G11: Pago | H11: Local Defillo
A12: 46051 | B12: La Cata DF | C12: Operación | D12: Trabajo | E12: 3400 | F12: Transferencia | G12: Pago | H12: Trabajo electrico: Henry Troncoso
A13: 46052 | B13: La Cata LMF | C13: Gastos Fijos | D13: Nomina | E13: 66250 | F13: Transferencia | G13: Pago | H13: Ambas Sucursales
A14: 46052 | B14: La Cata LMF | C14: Gastos Fijos | D14: Renta | E14: 40000 | F14: Transferencia | G14: Pago
A15: 46060 | B15: La Cata LMF | C15: Gastos Fijos | D15: TSS | E15: 10289.91 | F15: Transferencia | G15: Pago | H15: Seguro TSS
A16: 46060 | B16: La Cata LMF | C16: Gastos Fijos | D16: Infotep | E16: 545 | F16: Transferencia | G16: Pago
A17: 46064 | B17: La Cata LMF | C17: Operación | D17: Electricidad | E17: 25404.22 | F17: Transferencia | G17: Pendiente | H17: edesur
A18: 46067 | B18: La Cata DF | C18: Gastos Fijos | D18: Nomina | E18: 19750 | F18: Transferencia | G18: Pago | H18: Nomina
A19: 46067 | B19: La Cata LMF | C19: Gastos Fijos | D19: Nomina | E19: 39250 | F19: Transferencia | G19: Pago | H19: Nomina
A20: 46070 | B20: La Cata LMF | C20: Gastos Fijos | D20: Nomina | E20: 10000 | F20: Transferencia | G20: Pago | H20: Pago Contable LMF Enero y Febrero, pagada hasta mayo
A21: 46072 | B21: La Cata DF | C21: Operación | D21: Electricidad | E21: 25645.96 | F21: Transferencia | G21: Pago | H21: Mes de Enero 26, Edesur.
A22: 46072 | B22: La Cata DF | C22: Operación | D22: PedidosYa | E22: 8000 | F22: Transferencia | G22: Pago | H22: Pago Enlace a Pedidos Ya
A23: 46080 | B23: La Cata DF | C23: Gastos Fijos | D23: Nomina | E23: 19750 | F23: Transferencia | G23: Pago | H23: Nomina
A24: 46080 | B24: La Cata LMF | C24: Gastos Fijos | D24: Nomina | E24: 39250 | F24: Transferencia | G24: Pago | H24: Nomina
A25: 46080 | B25: La Cata LMF | C25: Gastos Fijos | D25: Renta | E25: 40000 | F25: Transferencia | G25: Pago
A26: 46080 | B26: La Cata LMF | C26: Gastos Fijos | D26: TSS | E26: 10833.15 | F26: Transferencia | G26: Pago | H26: Seguro TSS
A27: 46080 | B27: La Cata LMF | C27: Gastos Fijos | D27: Infotep | E27: 395 | F27: Transferencia | G27: Pago
A28: 46083 | B28: La Cata DF | C28: Gastos Fijos | D28: Renta | E28: 36000 | F28: Transferencia | G28: Pago | H28: Local Defillo
A29: 46106 | B29: La Cata DF | C29: Gastos Fijos | D29: Internet | E29: 5201.6 | F29: Transferencia | G29: Pago | H29: Local Defillo
A30: 46106 | B30: La Cata DF | C30: Gastos Fijos | D30: Electricidad | E30: 26236.88 | F30: Transferencia | G30: Pago | H30: Local Defillo
A31: 46112 | B31: La Cata DF | C31: Gastos Fijos | D31: Renta | E31: 36000 | F31: Transferencia | G31: Pago | H31: Local Defillo
A32: 46112 | B32: AMBAS | C32: Gastos Fijos | D32: Internet | E32: 9000 | F32: Transferencia | G32: Pago | H32: Pago Ignacio
A33: 46112 | B33: La Cata LMF | C33: Gastos Fijos | D33: Renta | E33: 40000 | F33: Transferencia | G33: Pago
A34: 46112 | B34: La Cata LMF | C34: Gastos Fijos | D34: TSS | E34: 7222.1 | F34: Transferencia | G34: Pago | H34: Seguro TSS
A35: 46112 | B35: La Cata LMF | C35: Operación | D35: Electricidad | E35: 23456.87 | F35: Transferencia | G35: Pago | H35: edesur
A36: 46129 | B36: La Cata DF | C36: Gastos Fijos | D36: Agua | E36: 950 | F36: Transferencia | G36: Pago | H36: Agua Defillo
A37: 46132 | B37: La Cata DF | C37: Operación | D37: Caja chica | E37: 3000 | F37: Transferencia | G37: Pago
A38: 46139 | B38: La Cata DF | C38: Gastos Fijos | D38: Renta | E38: 36000 | F38: Transferencia | G38: Pago | H38: Local Defillo
A39: 46139 | B39: La Cata LMF | C39: Gastos Fijos | D39: Renta | E39: 40000 | F39: Transferencia | G39: Pago | H39: LMF
A40: 46139 | B40: La Cata DF | C40: Operación | D40: Electricidad | E40: 36295.95 | F40: Transferencia | G40: Pago
...

Sheet CXP
A1: Semana (Lunes) | B1: UBICACION | C1: PROVEEDOR | D1: FACTURA | E1: FECHA FACTURA | F1: FECHA VENCIMIENTO | G1: TIPO (CREDITO/CONTADO) | H1: MONTO | I1: PAGO 1 | J1: FECHA PAGO 1 | K1: PAGO 2 | L1: FECHA PAGO 2 | M1: TOTAL PAGADO | N1: PAGADO (SI/NO) | O1: FECHA PAGO | P1: METODO PAGO | Q1: MONTO PENDIENTE | R1: DIAS A VENCER | S1: ALERTA | T1: Registrado por | U1: Validado | V1: Validado por | W1: Fecha validación | X1: NOTA
B2: La Cata DF | C2: UNITED BRANDS | D2: 16426 | E2: 46373 | F2: 46038 | G2: Crédito | H2: 58087.07 | M2: =SUM(I2,K2) | N2: Sí | Q2: =IF(N2="Sí",0,H2-I2-K2) | R2: =F2-TODAY() | S2: =IF(N2="Sí","🟢 Pagado",IF(R2<0,"🔴 Vencido",IF(R2<=7,"🟡 Por vencer","")))
B3: La Cata DF | C3: UNITED BRANDS | D3: 16439 | E3: 46011 | F3: 46041 | G3: Crédito | H3: 17050.19 | M3: =SUM(I3,K3) | N3: Sí | Q3: =IF(N3="Sí",0,H3-I3-K3) | R3: =F3-TODAY() | S3: =IF(N3="Sí","🟢 Pagado",IF(R3<0,"🔴 Vencido",IF(R3<=7,"🟡 Por vencer","")))
B4: La Cata DF | C4: UNITED BRANDS | D4: 16441 | E4: 46011 | F4: 46041 | G4: Crédito | H4: 15904.22 | M4: =SUM(I4,K4) | N4: Sí | Q4: =IF(N4="Sí",0,H4-I4-K4) | R4: =F4-TODAY() | S4: =IF(N4="Sí","🟢 Pagado",IF(R4<0,"🔴 Vencido",IF(R4<=7,"🟡 Por vencer","")))
B5: AMBAS | C5: JUAN BEATO | D5: TC QIK | E5: 46011 | F5: 46042 | G5: Crédito | H5: 359960 | I5: 347060.01 | K5: 12899.99 | L5: 46112 | M5: =SUM(I5,K5) | N5: Sí | Q5: =IF(N5="Sí",0,H5-I5-K5) | R5: =F5-TODAY() | S5: =IF(N5="Sí","🟢 Pagado",IF(R5<0,"🔴 Vencido",IF(R5<=7,"🟡 Por vencer","")))
B6: AMBAS | C6: JUAN BEATO | D6: TC 2564 Banesco | E6: 46012 | F6: 46054 | G6: Crédito | H6: 262167 | M6: =SUM(I6,K6) | N6: Sí | Q6: =IF(N6="Sí",0,H6-I6-K6) | R6: =F6-TODAY() | S6: =IF(N6="Sí","🟢 Pagado",IF(R6<0,"🔴 Vencido",IF(R6<=7,"🟡 Por vencer","")))
B7: La Cata DF | C7: JUAN BEATO | D7: GASTOS VARIOS | E7: 45940 | F7: 46096 | G7: Contado | H7: 7974.8 | I7: 7974.8 | M7: =SUM(I7,K7) | N7: Sí | O7: 46097 | Q7: =IF(N7="Sí",0,H7-I7-K7) | R7: =F7-TODAY() | S7: =IF(N7="Sí","🟢 Pagado",IF(R7<0,"🔴 Vencido",IF(R7<=7,"🟡 Por vencer","")))
B8: AMBAS | C8: JOSE IGNACIO ROA | D8: GASTOS VARIOS | E8: 45940 | F8: 46050 | G8: Contado | H8: 68200 | I8: 27290 | M8: =SUM(I8,K8) | N8: Sí | Q8: =IF(N8="Sí",0,H8-I8-K8) | R8: =F8-TODAY() | S8: =IF(N8="Sí","🟢 Pagado",IF(R8<0,"🔴 Vencido",IF(R8<=7,"🟡 Por vencer",""))) | X8: Extraido del archivo de Juan Beato, menos RD$50,000 motor
B9: La Cata LMF | C9: UNITED BRANDS | D9: 1645632 | E9: 46017 | F9: 46047 | G9: Crédito | H9: 81021.67 | I9: 630 | M9: =SUM(I9,K9) | N9: Sí | Q9: =IF(N9="Sí",0,H9-I9-K9) | R9: =F9-TODAY() | S9: =IF(N9="Sí","🟢 Pagado",IF(R9<0,"🔴 Vencido",IF(R9<=7,"🟡 Por vencer",""))) | X9: pendiente pagar a Juan Beato
B10: La Cata DF | C10: OXBAR | D10: 10144 | E10: 46041 | F10: 46059 | G10: Crédito | H10: 11984.45 | I10: 5992 | K10: 5992.45 | L10: 46072 | M10: =SUM(I10,K10) | N10: Sí | Q10: =IF(N10="Sí",0,H10-I10-K10) | R10: =F10-TODAY() | S10: =IF(N10="Sí","🟢 Pagado",IF(R10<0,"🔴 Vencido",IF(R10<=7,"🟡 Por vencer","")))
B11: La Cata DF | C11: JUAN BEATO | D11: TC | E11: 46040 | F11: 46075 | G11: Crédito | H11: 41344.99 | M11: =SUM(I11,K11) | N11: Sí | Q11: =IF(N11="Sí",0,H11-I11-K11) | R11: =F11-TODAY() | S11: =IF(N11="Sí","🟢 Pagado",IF(R11<0,"🔴 Vencido",IF(R11<=7,"🟡 Por vencer","")))
B12: La Cata LMF | C12: UNITED BRANDS | D12: 1646194 | E12: 46018 | F12: 46079 | G12: Crédito | H12: 100309.44 | I12: 100309.44 | M12: =SUM(I12,K12) | N12: Sí | Q12: =IF(N12="Sí",0,H12-I12-K12) | R12: =F12-TODAY() | S12: =IF(N12="Sí","🟢 Pagado",IF(R12<0,"🔴 Vencido",IF(R12<=7,"🟡 Por vencer",""))) | X12: pendiente pagar a Juan Beato
B13: La Cata LMF | C13: CND LMF | D13: TRANSFERENCIA | E13: 46043 | F13: 46051 | G13: Crédito | H13: 160521.84 | I13: 160521.84 | M13: =SUM(I13,K13) | N13: Sí | P13: Transferencia | Q13: =IF(N13="Sí",0,H13-I13-K13) | R13: =F13-TODAY() | S13: =IF(N13="Sí","🟢 Pagado",IF(R13<0,"🔴 Vencido",IF(R13<=7,"🟡 Por vencer","")))
B14: La Cata LMF | C14: LOCAL LMF | D14: TRANSFERENCIA | E14: 46021 | F14: 46051 | G14: Crédito | H14: 40000 | I14: 40000 | M14: =SUM(I14,K14) | N14: Sí | O14: 46053 | P14: Transferencia | Q14: =IF(N14="Sí",0,H14-I14-K14) | R14: =F14-TODAY() | S14: =IF(N14="Sí","🟢 Pagado",IF(R14<0,"🔴 Vencido",IF(R14<=7,"🟡 Por vencer","")))
B15: La Cata DF | C15: EDESUR DEFILLO | D15: NIC 44327 | E15: 46043 | F15: 46072 | G15: Crédito | H15: 25645.96 | I15: 25645.96 | J15: 46072 | M15: =SUM(I15,K15) | N15: Sí | O15: 46072 | Q15: =IF(N15="Sí",0,H15-I15-K15) | R15: =F15-TODAY() | S15: =IF(N15="Sí","🟢 Pagado",IF(R15<0,"🔴 Vencido",IF(R15<=7,"🟡 Por vencer","")))
B16: La Cata LMF | C16: UNITED BRANDS | D16: 1647227 | E16: 46021 | F16: 46052 | G16: Crédito | H16: 191510.11 | I16: 191510.11 | M16: =SUM(I16,K16) | N16: Sí | Q16: =IF(N16="Sí",0,H16-I16-K16) | R16: =F16-TODAY() | S16: =IF(N16="Sí","🟢 Pagado",IF(R16<0,"🔴 Vencido",IF(R16<=7,"🟡 Por vencer","")))
B17: La Cata DF | C17: FRANCELIS SANCHEZ | D17: TC | E17: 46043 | F17: 46081 | G17: Crédito | H17: 820 | I17: 820 | J17: 46084 | M17: =SUM(I17,K17) | N17: Sí | O17: 46084 | Q17: =IF(N17="Sí",0,H17-I17-K17) | R17: =F17-TODAY() | S17: =IF(N17="Sí","🟢 Pagado",IF(R17<0,"🔴 Vencido",IF(R17<=7,"🟡 Por vencer","")))
B18: La Cata DF | C18: JUAN BEATO | D18: TC | E18: 46012 | F18: 46081 | G18: Crédito | H18: 13110 | I18: 13110 | J18: 46084 | M18: =SUM(I18,K18) | N18: Sí | O18: 46084 | Q18: =IF(N18="Sí",0,H18-I18-K18) | R18: =F18-TODAY() | S18: =IF(N18="Sí","🟢 Pagado",IF(R18<0,"🔴 Vencido",IF(R18<=7,"🟡 Por vencer","")))
B19: La Cata LMF | C19: SUPERNOVA /TULIPAN/DELVIS | D19: 3104 | E19: 46038 | F19: 46052 | G19: Crédito | H19: 87905 | I19: 73844.99 | M19: =SUM(I19,K19) | N19: Sí | O19: 46057 | Q19: =IF(N19="Sí",0,H19-I19-K19) | R19: =F19-TODAY() | S19: =IF(N19="Sí","🟢 Pagado",IF(R19<0,"🔴 Vencido",IF(R19<=7,"🟡 Por vencer","")))
B20: La Cata LMF | C20: JOSE IGNACIO ROA | D20: TRANSFERENCIA | E20: 46035 | F20: 46052 | G20: Contado | H20: 1750 | I20: 1750 | M20: =SUM(I20,K20) | N20: Sí | Q20: =IF(N20="Sí",0,H20-I20-K20) | R20: =F20-TODAY() | S20: =IF(N20="Sí","🟢 Pagado",IF(R20<0,"🔴 Vencido",IF(R20<=7,"🟡 Por vencer",""))) | X20: HIELO LMF
B21: La Cata LMF | C21: JOSE IGNACIO ROA | D21: TRANSFERENCIA | E21: 46040 | F21: 46052 | G21: Contado | H21: 1350 | I21: 1350 | M21: =SUM(I21,K21) | N21: Sí | Q21: =IF(N21="Sí",0,H21-I21-K21) | R21: =F21-TODAY() | S21: =IF(N21="Sí","🟢 Pagado",IF(R21<0,"🔴 Vencido",IF(R21<=7,"🟡 Por vencer",""))) | X21: CENA LMF DEGUSTACION
B22: La Cata LMF | C22: JOSE IGNACIO ROA | D22: TRANSFERENCIA | E22: 46041 | F22: 46052 | G22: Contado | H22: 2000 | I22: 2000 | M22: =SUM(I22,K22) | N22: Sí | Q22: =IF(N22="Sí",0,H22-I22-K22) | R22: =F22-TODAY() | S22: =IF(N22="Sí","🟢 Pagado",IF(R22<0,"🔴 Vencido",IF(R22<=7,"🟡 Por vencer",""))) | X22: MULTA SOLTERO
B23: La Cata LMF | C23: SUPERNOVA /TULIPAN/DELVIS | D23: 3134 | E23: 46045 | F23: 46059 | G23: Crédito | H23: 158515 | I23: 1000 | M23: =SUM(I23,K23) | N23: Sí | O23: 46057 | Q23: =IF(N23="Sí",0,H23-I23-K23) | R23: =F23-TODAY() | S23: =IF(N23="Sí","🟢 Pagado",IF(R23<0,"🔴 Vencido",IF(R23<=7,"🟡 Por vencer","")))
B24: La Cata DF | C24: JUAN BEATO | D24: TC | E24: 46049 | F24: 46069 | G24: Crédito | H24: 10222.49 | I24: 1400 | M24: =SUM(I24,K24) | N24: Sí | Q24: =IF(N24="Sí",0,H24-I24-K24) | R24: =F24-TODAY() | S24: =IF(N24="Sí","🟢 Pagado",IF(R24<0,"🔴 Vencido",IF(R24<=7,"🟡 Por vencer","")))
B25: La Cata LMF | C25: SUPERNOVA /TULIPAN/DELVIS | D25: 3146 | E25: 46043 | F25: 46059 | G25: Crédito | H25: 11680 | I25: 1000 | M25: =SUM(I25,K25) | N25: Sí | O25: 46057 | Q25: =IF(N25="Sí",0,H25-I25-K25) | R25: =F25-TODAY() | S25: =IF(N25="Sí","🟢 Pagado",IF(R25<0,"🔴 Vencido",IF(R25<=7,"🟡 Por vencer","")))
B26: AMBAS | C26: JUAN BEATO | D26: TC | E26: 46050 | F26: 46091 | G26: Crédito | H26: 181331.11 | I26: 181331.11 | M26: =SUM(I26,K26) | N26: Sí | O26: 46091 | Q26: =IF(N26="Sí",0,H26-I26-K26) | R26: =F26-TODAY() | S26: =IF(N26="Sí","🟢 Pagado",IF(R26<0,"🔴 Vencido",IF(R26<=7,"🟡 Por vencer",""))) | X26: Pagos facturas United Brands el 28 Enero por TC
B27: La Cata LMF | C27: JOSE IGNACIO ROA | D27: TRANSFERENCIA | E27: 46050 | G27: Contado | H27: 1000 | I27: 1000 | M27: =SUM(I27,K27) | N27: Sí | Q27: =IF(N27="Sí",0,H27-I27-K27) | R27: =F27-TODAY() | S27: =IF(N27="Sí","🟢 Pagado",IF(R27<0,"🔴 Vencido",IF(R27<=7,"🟡 Por vencer",""))) | X27: PAGO A SOTERO
B28: La Cata LMF | C28: JOSE IGNACIO ROA | D28: TRANSFERENCIA | E28: 46051 | G28: Contado | H28: 1400 | I28: 1400 | M28: =SUM(I28,K28) | N28: Sí | Q28: =IF(N28="Sí",0,H28-I28-K28) | R28: =F28-TODAY() | S28: =IF(N28="Sí","🟢 Pagado",IF(R28<0,"🔴 Vencido",IF(R28<=7,"🟡 Por vencer",""))) | X28: AGUA SUBLIME
B29: La Cata LMF | C29: SUPERNOVA /TULIPAN/DELVIS | D29: 3163 | E29: 46051 | F29: 46055 | G29: Crédito | H29: 193848.03 | I29: 193848.03 | M29: =SUM(I29,K29) | N29: Sí | O29: 46062 | Q29: =IF(N29="Sí",0,H29-I29-K29) | R29: =F29-TODAY() | S29: =IF(N29="Sí","🟢 Pagado",IF(R29<0,"🔴 Vencido",IF(R29<=7,"🟡 Por vencer","")))
B30: AMBAS | C30: TUBEBIDA.NET( Hollandia) | D30: 2120 | E30: 46053 | F30: 46081 | G30: Crédito | H30: 43999.99 | I30: 43999.99 | J30: 46076 | M30: =SUM(I30,K30) | N30: Sí | O30: 46076 | Q30: =IF(N30="Sí",0,H30-I30-K30) | R30: =F30-TODAY() | S30: =IF(N30="Sí","🟢 Pagado",IF(R30<0,"🔴 Vencido",IF(R30<=7,"🟡 Por vencer",""))) | X30: CERVEZAS HOLLANDIA
B31: La Cata LMF | C31: JOSE IGNACIO ROA | D31: TRANSFERENCIA | E31: 46053 | G31: Contado | H31: 1000 | I31: 1000 | M31: =SUM(I31,K31) | N31: Sí | Q31: =IF(N31="Sí",0,H31-I31-K31) | R31: =F31-TODAY() | S31: =IF(N31="Sí","🟢 Pagado",IF(R31<0,"🔴 Vencido",IF(R31<=7,"🟡 Por vencer",""))) | X31: PAGO A ORLANDITO
B32: La Cata DF | C32: JUAN BEATO | D32: TC | E32: 46053 | F32: 46092 | G32: Crédito | H32: 27290 | I32: 27290 | M32: =SUM(I32,K32) | N32: Sí | O32: 46097 | Q32: =IF(N32="Sí",0,H32-I32-K32) | R32: =F32-TODAY() | S32: =IF(N32="Sí","🟢 Pagado",IF(R32<0,"🔴 Vencido",IF(R32<=7,"🟡 Por vencer","")))
B33: La Cata DF | C33: JUAN BEATO | D33: TC | E33: 46053 | F33: 46092 | G33: Crédito | H33: 630 | I33: 630 | M33: =SUM(I33,K33) | N33: Sí | O33: 46097 | Q33: =IF(N33="Sí",0,H33-I33-K33) | R33: =F33-TODAY() | S33: =IF(N33="Sí","🟢 Pagado",IF(R33<0,"🔴 Vencido",IF(R33<=7,"🟡 Por vencer",""))) | X33: Material gastable
B34: La Cata LMF | C34: SUPERNOVA /TULIPAN/DELVIS | D34: 3184 | E34: 46058 | F34: 46070 | G34: Crédito | H34: =192310-6420 | I34: 185890 | J34: 46069 | M34: =SUM(I34,K34) | N34: Sí | O34: 46069 | Q34: =IF(N34="Sí",0,H34-I34-K34) | R34: =F34-TODAY() | S34: =IF(N34="Sí","🟢 Pagado",IF(R34<0,"🔴 Vencido",IF(R34<=7,"🟡 Por vencer",""))) | X34: Restamos RON MACORIX RD$6,420.00, MONTO ORIGINAL RD$192,310.00
B35: La Cata LMF | C35: JUAN BEATO | D35: TC | E35: 46059 | F35: 46086 | G35: Crédito | H35: 73844.99 | I35: 73844.99 | J35: 46084 | M35: =SUM(I35,K35) | N35: Sí | O35: 46084 | Q35: =IF(N35="Sí",0,H35-I35-K35) | R35: =F35-TODAY() | S35: =IF(N35="Sí","🟢 Pagado",IF(R35<0,"🔴 Vencido",IF(R35<=7,"🟡 Por vencer","")))
B36: La Cata LMF | C36: JUAN BEATO | D36: UB a Beato | E36: 46061 | F36: 46109 | G36: Crédito | H36: 282551.59 | I36: 282551.59 | J36: 46112 | M36: =SUM(I36,K36) | N36: Sí | Q36: =IF(N36="Sí",0,H36-I36-K36) | R36: =F36-TODAY() | S36: =IF(N36="Sí","🟢 Pagado",IF(R36<0,"🔴 Vencido",IF(R36<=7,"🟡 Por vencer","")))
B37: La Cata LMF | C37: SUPERNOVA /TULIPAN/DELVIS | D37: 3211 | E37: 46065 | F37: 46077 | G37: Crédito | H37: 247915 | I37: 247915 | J37: 46077 | M37: =SUM(I37,K37) | N37: Sí | O37: 46077 | Q37: =IF(N37="Sí",0,H37-I37-K37) | R37: =F37-TODAY() | S37: =IF(N37="Sí","🟢 Pagado",IF(R37<0,"🔴 Vencido",IF(R37<=7,"🟡 Por vencer","")))
B38: La Cata DF | C38: JUAN BEATO | D38: TC 5309 | E38: 46066 | F38: 46108 | G38: Crédito | H38: 23688.64 | I38: 23688.64 | J38: 46112 | M38: =SUM(I38,K38) | N38: Sí | Q38: =IF(N38="Sí",0,H38-I38-K38) | R38: =F38-TODAY() | S38: =IF(N38="Sí","🟢 Pagado",IF(R38<0,"🔴 Vencido",IF(R38<=7,"🟡 Por vencer",""))) | X38: PEDIDO ALMACENES HATUEY SRL 148476
B39: La Cata DF | C39: JUAN BEATO | D39: 1 | E39: 46066 | F39: 46071 | G39: Crédito | H39: 925 | M39: =SUM(I39,K39) | N39: Sí | Q39: =IF(N39="Sí",0,H39-I39-K39) | R39: =F39-TODAY() | S39: =IF(N39="Sí","🟢 Pagado",IF(R39<0,"🔴 Vencido",IF(R39<=7,"🟡 Por vencer",""))) | X39: Material gastable
B40: La Cata DF | C40: JUAN BEATO | D40: 2 | E40: 46067 | F40: 46069 | G40: Crédito | H40: 264 | M40: =SUM(I40,K40) | N40: Sí | Q40: =IF(N40="Sí",0,H40-I40-K40) | R40: =F40-TODAY() | S40: =IF(N40="Sí","🟢 Pagado",IF(R40<0,"🔴 Vencido",IF(R40<=7,"🟡 Por vencer",""))) | X40: Impresion oferta 6x5
...

Sheet Cata SJM
A1: Presupuesto Total | B1: 800000 | D1: Inversion Ignacio | E1: =SUMIFS(I:I,B:B,"Ignacio",G:G,"Pagado")
A2: Total Invertido | B2: =SUMIFS(I:I,G:G,"Pagado") | D2: Inversion Beato | E2: =SUMIFS(I:I,B:B,"Beato",G:G,"Pagado")
A3: Total Pendiente | B3: =SUMIFS(I:I,G:G,"Pendiente") | D3: Inversion La Cata | E3: =SUMIFS(I:I,B:B,"La Cata",G:G,"Pagado")
A4: Disponible Presupuesto | B4: =B1-(B2+B3) | D4: Total Capital Invertido | E4: =SUM(E1:E3)
A7: Fecha | B7: Pagado por | C7: Categoría | D7: Descripción | E7: Proveedor | F7: Método de pago | G7: Pagado a Suplidor | H7: Pago Inversionista | I7: Monto | J7: Fecha de pago Inversionista | K7: Notas
A8: 46105 | B8: Ignacio | C8: Renta | D8: Depositos de Alquiler | F8: Transferencia | G8: Pagado | H8: Pendiente | I8: 135000 | K8: 2+1 depositos de alquiler
A9: 46105 | B9: Ignacio | C9: Seguridad | D9: Camaras | F9: Transferencia | G9: Pagado | H9: Pendiente | I9: 162911 | K9: 13 Camaras + 1 router +cables red
A10: 46107 | B10: Ignacio | C10: Sonido | D10: Bocina | F10: Transferencia | G10: Pagado | H10: Pendiente | I10: 5400 | K10: 2 Bocinas
A11: 46112 | B11: Ignacio | C11: Pintura | D11: Pintura fuera del local | F11: Transferencia | G11: Pagado | H11: Pendiente | I11: 23500 | K11: 6 galones de pintura, tiner y mano de obra
A12: 46114 | B12: Beato | C12: Seguridad | D12: Cables Camara | F12: Tarjeta | G12: Pagado | H12: Pendiente | I12: 3400 | K12: Agregar metodo de pago Tarjeta de Credito
A13: 46121 | B13: Ignacio | C13: Techo | D13: Mano de Obra Techo y Division | E13: Maestro Bonvi | F13: Efectivo | G13: Pagado | H13: Pendiente | I13: 50000 | K13: Adelante de la mano de obra
A14: 46120 | B14: La Cata | C14: Techo | D14: Aluzinc y Materiales | E14: Ferreteria Prisma | F14: Transferencia | G14: Pagado | H14: Pendiente | I14: 55000
A15: 46120 | B15: La Cata | C15: Techo | D15: Perfiles y tornillos | E15: Ferreteria Prisma | F15: Transferencia | G15: Pagado | H15: Pendiente | I15: 15000
A16: 46120 | B16: La Cata | C16: Techo | D16: Madera y Clavos | E16: Ferreteria Prisma | F16: Transferencia | G16: Pagado | H16: Pendiente | I16: 4475
A17: 46121 | B17: Ignacio | C17: Techo PVC | D17: Adelanto y tumbado de Techo | E17: Maestro Melvin | F17: Transferencia | G17: Pagado | H17: Pendiente | I17: 20000
A18: 46118 | B18: La Cata | C18: Letrero | D18: Pago 50% Letrero | E18: Dexter Graphics | F18: Transferencia | G18: Pagado | H18: Pendiente | I18: 60000 | K18: Adelanto por el 50% del trabajo del letrero
A19: 46121 | B19: Ignacio | C19: Vidrios y Puertas | D19: Abono | E19: Maestro Ayendi | F19: Transferencia | G19: Pagado | H19: Pendiente | I19: 50000
A20: 46122 | B20: Ignacio | C20: Materiales | D20: Materiales para contruccion de meseta y banos | E20: Ferreteria Humberto | F20: Transferencia | G20: Pagado | H20: Pendiente | I20: 45440 | K20: Materiales para la pared, division, banos etc.
A21: 46122 | B21: Beato | C21: Materiales Techo PVC | D21: Materiales Techo PVC | E21: Max Ferreteria | F21: Tarjeta | G21: Pagado | H21: Pendiente | I21: 29458.04
A22: 46122 | B22: Beato | C22: Materiales Techo PVC | D22: Materiales Techo PVC | E22: Cielos Acusticos | F22: Tarjeta | G22: Pagado | H22: Pendiente | I22: 64779.17
A23: 38817 | B23: Ignacio | C23: Transporte | D23: Materiales Techo PVC | E23: Sotero | F23: Transferencia | G23: Pagado | H23: Pendiente | I23: 6000
A24: 46123 | B24: Ignacio | C24: Electricidad | D24: Materiales | E24: Maestro Pachi | F24: Transferencia | G24: Pagado | H24: Pendiente | I24: 3500 | K24: Materialies para extension alto voltaje
A25: 46125 | B25: Ignacio | C25: Techo | D25: Materiales | E25: Ferreteria Prisma | F25: Transferencia | G25: Pagado | H25: Pendiente | I25: 15700
A26: 46125 | B26: Ignacio | C26: Cable Bocinas | D26: Bocinas | E26: Amazon | F26: Tarjeta | G26: Pagado | H26: Pendiente | I26: 3900 | K26: 200 pies de cable audio 14amp
A27: 46130 | B27: Ignacio | C27: Letrero | D27: Pago 50% Letrero | E27: Dexter Graphics | F27: Transferencia | G27: Pagado | H27: Pendiente | I27: 60000
A28: 46134 | B28: Ignacio | C28: Muebles | D28: Abono Muebles y mesas alta | E28: Tio Nelson | F28: Transferencia | G28: Pagado | H28: Pendiente | I28: 40000 | K28: Restan 18mil, y la tapiceria del mueble.
A29: 46134 | B29: Ignacio | C29: Ceramica | D29: Ceramica Meseta | E29: Ramizaba Terminaciones | F29: Transferencia | G29: Pagado | H29: Pendiente | I29: 4896
A30: 46134 | B30: Ignacio | C30: Materiales | D30: 6 fundas de pegatin y barillas | E30: Tio Moreno | F30: Transferencia | G30: Pagado | H30: Pendiente | I30: 4000
A31: 46134 | B31: Ignacio | C31: Materiales | D31: Plomeria bano | E31: Ferreteria Prisma | F31: Transferencia | G31: Pagado | H31: Pendiente | I31: 1101
A32: 46135 | B32: Ignacio | C32: Ceramica | D32: Cermica piso bano etc. | E32: Ramizaba Terminaciones | F32: Transferencia | G32: Pagado | H32: Pendiente | I32: 6288
A33: 46135 | B33: Ignacio | C33: Ceramica | D33: Cermica piso bano etc. | E33: Ramizaba Terminaciones | F33: Transferencia | G33: Pagado | H33: Pendiente | I33: 2100
A34: 46136 | B34: Ignacio | C34: Materiales | D34: Materiales faltantes | E34: Ferreteria Prisma | F34: Transferencia | G34: Pagado | H34: Pendiente | I34: 4697
A35: 46132 | B35: Ignacio | C35: Sueldo | D35: Pago sueldo | E35: Valdez | F35: Transferencia | G35: Pagado | H35: Pendiente | I35: 5000 | K35: Valdez es quien abre y cierra el local y nos esta asistiendo con las compras y asugrando que nadie va a poner mano alla.
A36: 46136 | B36: Ignacio | C36: Construcion | D36: Adelanto Mano de obra | E36: Maestro Bonvi | F36: Transferencia | G36: Pagado | H36: Pendiente | I36: 30000
A37: 46137 | B37: Ignacio | C37: Construcion | D37: Materiales faltantes | E37: Ferreteria Prisma | F37: Transferencia | G37: Pagado | H37: Pendiente | I37: 1220
A38: 46137 | B38: Ignacio | C38: Construcion | D38: Materiales faltantes | E38: Ferreteria Prisma | F38: Transferencia | G38: Pagado | H38: Pendiente | I38: 1535
A39: 46140 | B39: Ignacio | C39: Construcion | D39: Materiales faltantes | E39: Ferreteria Luz | F39: Transferencia | G39: Pagado | H39: Pendiente | I39: 1170
A40: 46141 | B40: Ignacio | C40: Techo | D40: Materiales faltantes | E40: Ferreteria Prisma | F40: Transferencia | G40: Pagado | H40: Pendiente | I40: 13215
A41: 46141 | B41: Ignacio | C41: Construcion | D41: Cermica piso bano etc. | E41: Ramizaba Terminaciones | F41: Transferencia | G41: Pagado | H41: Pendiente | I41: 612
A42: 46141 | B42: Beato | C42: Abanicos | D42: 4 Abanicos | E42: Innovacentro | F42: Tarjeta | G42: Pagado | H42: Pendiente | I42: 15539.99
...

Sheet Análisis CXP
B2: 📊 ANÁLISIS DE CUENTAS POR PAGAR (CXP) - LA CATA
B3: =CONCATENATE("Análisis generado: ",TEXT(TODAY(),"d")," de ",TEXT(TODAY(),"mmmm")," de ",TEXT(TODAY(),"yyyy"))
B5: 📋 TOTAL REGISTROS | C5: 💰 MONTO TOTAL | D5: ⏳ PENDIENTE | E5: ✅ TASA PAGO | F5: 🏢 PROVEEDORES
B6: =COUNTA(CXP!B:B)-1 | C6: =SUM(CXP!H:H) | D6: =SUM(CXP!Q:Q) | E6: =IF(C6=0,0,1-(D6/C6)) | F6: {=ROWS(_xlfn.UNIQUE(_xlfn._xlws.FILTER(CXP!C2:C5000,CXP!C2:C5000<>"")))-1+1}
B8: 🚦 ESTADO DE PAGOS | F8: 🏢 MONTO POR UBICACIÓN
B9: Estado | C9: Cantidad | D9: Porcentaje | F9: Ubicación | G9: Monto Total | H9: Pendiente
B10: 🟢 Pagado | C10: =COUNTIFS(CXP!S:S,"*Pagado*",CXP!B:B,"<>") | D10: =IF($B$6=0,0,C10/$B$6) | F10: La Cata LMF | G10: =SUMIF(CXP!B:B,F10,CXP!H:H) | H10: =SUMIF(CXP!B:B,F10,CXP!Q:Q)
B11: 🔴 Vencido | C11: =COUNTIFS(CXP!S:S,"*Vencido*",CXP!B:B,"<>") | D11: =IF($B$6=0,0,C11/$B$6) | F11: AMBAS | G11: =SUMIF(CXP!B:B,F11,CXP!H:H) | H11: =SUMIF(CXP!B:B,F11,CXP!Q:Q)
B12: 🟡 Por vencer | C12: =COUNTIFS(CXP!S:S,"*Por vencer*",CXP!B:B,"<>") | D12: =IF($B$6=0,0,C12/$B$6) | F12: La Cata DF | G12: =SUMIF(CXP!B:B,F12,CXP!H:H) | H12: =SUMIF(CXP!B:B,F12,CXP!Q:Q)
B13: Sin estado | C13: =B6-C10-C11-C12 | D13: =IF($B$6=0,0,C13/$B$6) | F13: La Cata SJM | G13: =SUMIF(CXP!B:B,F13,CXP!H:H) | H13: =SUMIF(CXP!B:B,F13,CXP!Q:Q)
B15: 🏆 TOP 10 PROVEEDORES POR MONTO | F15: ⚠️ MAYOR PENDIENTE POR PAGAR
B16: Proveedor | C16: Monto Total | F16: Proveedor | G16: Pendiente
B17: {=_xlfn.LET(_xlpm.provs,_xlfn.UNIQUE(_xlfn._xlws.FILTER(CXP!C:C,CXP!C:C<>"")),_xlpm.montos,SUMIF(CXP!C:C,_xlpm.provs,CXP!H:H),_xlpm.sorted,_xlfn.SORTBY(_xlfn.HSTACK(_xlpm.provs,_xlpm.montos),_xlpm.montos,-1),_xlfn.TAKE(_xlpm.sorted,10))} | C17: 7567616.6 | F17: {=_xlfn.LET(_xlpm.provs,_xlfn.UNIQUE(_xlfn._xlws.FILTER(CXP!C:C,CXP!C:C<>"")),_xlpm.pends,SUMIF(CXP!C:C,_xlpm.provs,CXP!Q:Q),_xlpm.filtered,_xlfn._xlws.FILTER(_xlfn.HSTACK(_xlpm.provs,_xlpm.pends),_xlpm.pends>0),_xlpm.sorted,_xlfn.SORTBY(_xlpm.filtered,INDEX(_xlpm.filtered,,2),-1),_xlfn.TAKE(_xlpm.sorted,8))} | G17: 1953090.8
B18: SUPERNOVA /TULIPAN/DELVIS | C18: 7245995.7 | F18: JOSE IGNACIO ROA | G18: 1151431
B19: CERVECERIA NACIONAL DOMINICANA SA | C19: 4652231.1 | F19: SUPERNOVA /TULIPAN/DELVIS | G19: 1113173
B20: UNITED BRANDS | C20: 2397420.9 | F20: UNITED BRANDS | G20: 676726.69
B21: JOSE IGNACIO ROA | C21: 1682084.2 | F21: UTENA GROUP | G21: 64142.95
B22: TUBEBIDA.NET( Hollandia) | C22: 238640.18 | F22: CABEZA LIQUORS | G22: 37799.99
B23: CABEZA LIQUORS STORE | C23: 211656.28 | F23: BEERS & CO | G23: 6807.52
B24: CND LMF | C24: 160521.84
B25: FRITO LAY DOMINICANA S A | C25: 140830.7
B26: DGI | C26: 116242.76
B28: =_xlfn.CONCAT("📅 PAGOS DE LA SEMANA: ",TEXT(TODAY()+MOD(9-WEEKDAY(TODAY()),7),"DD/MM/YYYY")," - ",TEXT(TODAY()+MOD(9-WEEKDAY(TODAY()),7)+6,"DD/MM/YYYY")) | I28: Semana: | J28: =TODAY()+MOD(9-WEEKDAY(TODAY()),7) | K28: =J28+6
B30: 💰 Total a Pagar: | C30: =SUMIFS(CXP!$Q:$Q,CXP!$F:$F,">="&$J$28,CXP!$F:$F,"<="&$K$28,CXP!$N:$N,"No",CXP!$Q:$Q,">0") | D30: 📋 Facturas: | E30: =COUNTIFS(CXP!$F:$F,">="&$J$28,CXP!$F:$F,"<="&$K$28,CXP!$N:$N,"No",CXP!$Q:$Q,">0") | F30: 🏢 Proveedores: | G30: {=IFERROR(ROWS(_xlfn.UNIQUE(_xlfn._xlws.FILTER(CXP!$C$2:$C$5000,(CXP!$F$2:$F$5000>=$J$28)*(CXP!$F$2:$F$5000<=$K$28)*(CXP!$N$2:$N$5000="No")*(CXP!$Q$2:$Q$5000>0)))),0)}
B32: =_xlfn.CONCAT("⚠️ VENCIDAS (antes de ",TEXT($J$28,"DD/MM"),"):") | D32: =SUMIFS(CXP!$Q:$Q,CXP!$F:$F,"<"&$J$28,CXP!$N:$N,"No",CXP!$Q:$Q,">0") | F32: =_xlfn.CONCAT("(",COUNTIFS(CXP!$F:$F,"<"&$J$28,CXP!$N:$N,"No",CXP!$Q:$Q,">0")," facturas)")
B34: 📆 Por Día | C34: Fecha | D34: Facturas | E34: Monto
B35: Lunes | C35: =$J$28+0 | D35: =COUNTIFS(CXP!$F:$F,$J$28+0,CXP!$N:$N,"No",CXP!$Q:$Q,">0") | E35: =SUMIFS(CXP!$Q:$Q,CXP!$F:$F,$J$28+0,CXP!$N:$N,"No",CXP!$Q:$Q,">0")
B36: Martes | C36: =$J$28+1 | D36: =COUNTIFS(CXP!$F:$F,$J$28+1,CXP!$N:$N,"No",CXP!$Q:$Q,">0") | E36: =SUMIFS(CXP!$Q:$Q,CXP!$F:$F,$J$28+1,CXP!$N:$N,"No",CXP!$Q:$Q,">0")
B37: Miércoles | C37: =$J$28+2 | D37: =COUNTIFS(CXP!$F:$F,$J$28+2,CXP!$N:$N,"No",CXP!$Q:$Q,">0") | E37: =SUMIFS(CXP!$Q:$Q,CXP!$F:$F,$J$28+2,CXP!$N:$N,"No",CXP!$Q:$Q,">0")
B38: Jueves | C38: =$J$28+3 | D38: =COUNTIFS(CXP!$F:$F,$J$28+3,CXP!$N:$N,"No",CXP!$Q:$Q,">0") | E38: =SUMIFS(CXP!$Q:$Q,CXP!$F:$F,$J$28+3,CXP!$N:$N,"No",CXP!$Q:$Q,">0")
B39: Viernes | C39: =$J$28+4 | D39: =COUNTIFS(CXP!$F:$F,$J$28+4,CXP!$N:$N,"No",CXP!$Q:$Q,">0") | E39: =SUMIFS(CXP!$Q:$Q,CXP!$F:$F,$J$28+4,CXP!$N:$N,"No",CXP!$Q:$Q,">0")
B40: Sábado | C40: =$J$28+5 | D40: =COUNTIFS(CXP!$F:$F,$J$28+5,CXP!$N:$N,"No",CXP!$Q:$Q,">0") | E40: =SUMIFS(CXP!$Q:$Q,CXP!$F:$F,$J$28+5,CXP!$N:$N,"No",CXP!$Q:$Q,">0")
B41: Domingo | C41: =$J$28+6 | D41: =COUNTIFS(CXP!$F:$F,$J$28+6,CXP!$N:$N,"No",CXP!$Q:$Q,">0") | E41: =SUMIFS(CXP!$Q:$Q,CXP!$F:$F,$J$28+6,CXP!$N:$N,"No",CXP!$Q:$Q,">0")
B42: TOTAL SEMANA | D42: =SUM(D35:D41) | E42: =SUM(E35:E41)
B44: 🧾 DETALLE PENDIENTE POR PROVEEDOR (Semana + Vencidas)
B45: Proveedor | C45: Pendiente Semana | D45: Vencido | E45: TOTAL PENDIENTE | F45: Facturas | G45: Prioridad
B46: {=IFERROR(_xlfn._xlws.SORT(_xlfn.UNIQUE(_xlfn._xlws.FILTER(CXP!$C$2:$C$5000,(CXP!$Q$2:$Q$5000>0)*(CXP!$N$2:$N$5000="No")))),"Sin pendientes")} | C46: {=IFERROR(_xlfn.MAP(_xlfn.ANCHORARRAY(B46),_xlfn.LAMBDA(_xlpm.prov,SUMIFS(CXP!$Q$2:$Q$5000,CXP!$C$2:$C$5000,_xlpm.prov,CXP!$F$2:$F$5000,">="&$J$28,CXP!$F$2:$F$5000,"<="&$K$28,CXP!$N$2:$N$5000,"No"))),0)} | D46: {=IFERROR(_xlfn.MAP(_xlfn.ANCHORARRAY(B46),_xlfn.LAMBDA(_xlpm.prov,SUMIFS(CXP!$Q$2:$Q$5000,CXP!$C$2:$C$5000,_xlpm.prov,CXP!$F$2:$F$5000,"<"&$J$28,CXP!$N$2:$N$5000,"No"))),0)} | E46: {=_xlfn.ANCHORARRAY(C46)+_xlfn.ANCHORARRAY(D46)} | F46: {=IFERROR(_xlfn.MAP(_xlfn.ANCHORARRAY(B46),_xlfn.LAMBDA(_xlpm.prov,COUNTIFS(CXP!$C$2:$C$5000,_xlpm.prov,CXP!$Q$2:$Q$5000,">0",CXP!$N$2:$N$5000,"No"))),0)} | G46: {=IFERROR(_xlfn.MAP(_xlfn.ANCHORARRAY(D46),_xlfn.LAMBDA(_xlpm.venc,IF(_xlpm.venc>0,"🔴 URGENTE",IF(C46>0,"🟡 ESTA SEMANA","🟢 OK")))),"")}
B47: 📊 TOTAL PENDIENTE | C47: =SUM(_xlfn.ANCHORARRAY(C46)) | D47: =SUM(_xlfn.ANCHORARRAY(D46)) | E47: =SUM(_xlfn.ANCHORARRAY(E46)) | F47: =SUM(_xlfn.ANCHORARRAY(F46))
B49: ⚠️ FACTURAS VENCIDAS (Requieren Atención Inmediata)
B50: Proveedor | C50: Factura | D50: Fecha Venc. | E50: Días Vencida | F50: Monto Pendiente | G50: Ubicación
...

Sheet Comparativo
A1: 📊 DASHBOARD COMPARATIVO - LA CATA | N1: Fecha Referencia: | O1: =TODAY()
A3: 📅 VENTAS SEMANA ACTUAL
A4: Día | B4: Fecha | C4: La Cata LMF | D4: La Cata DF | E4: La Cata SJM | F4: TOTAL DÍA | G4: % vs Promedio
A5: Lunes | B5: =$O$1-WEEKDAY($O$1,2)+1 | C5: =SUMIFS('Ventas Diarias'!$J:$J,'Ventas Diarias'!$A:$A,B5,'Ventas Diarias'!$B:$B,"La Cata LMF") | D5: =SUMIFS('Ventas Diarias'!$J:$J,'Ventas Diarias'!$A:$A,B5,'Ventas Diarias'!$B:$B,"La Cata DF") | E5: =SUMIFS('Ventas Diarias'!$J:$J,'Ventas Diarias'!$A:$A,B5,'Ventas Diarias'!$B:$B,"La Cata SJM") | F5: =C5+D5+E5 | G5: =IFERROR(F5/AVERAGE('Ventas Diarias'!$J:$J)-1,0)
A6: Martes | B6: =$O$1-WEEKDAY($O$1,2)+2 | C6: =SUMIFS('Ventas Diarias'!$J:$J,'Ventas Diarias'!$A:$A,B6,'Ventas Diarias'!$B:$B,"La Cata LMF") | D6: =SUMIFS('Ventas Diarias'!$J:$J,'Ventas Diarias'!$A:$A,B6,'Ventas Diarias'!$B:$B,"La Cata DF") | E6: =SUMIFS('Ventas Diarias'!$J:$J,'Ventas Diarias'!$A:$A,B6,'Ventas Diarias'!$B:$B,"La Cata SJM") | F6: =C6+D6+E6 | G6: =IFERROR(F6/AVERAGE('Ventas Diarias'!$J:$J)-1,0)
A7: Miércoles | B7: =$O$1-WEEKDAY($O$1,2)+3 | C7: =SUMIFS('Ventas Diarias'!$J:$J,'Ventas Diarias'!$A:$A,B7,'Ventas Diarias'!$B:$B,"La Cata LMF") | D7: =SUMIFS('Ventas Diarias'!$J:$J,'Ventas Diarias'!$A:$A,B7,'Ventas Diarias'!$B:$B,"La Cata DF") | E7: =SUMIFS('Ventas Diarias'!$J:$J,'Ventas Diarias'!$A:$A,B7,'Ventas Diarias'!$B:$B,"La Cata SJM") | F7: =C7+D7+E7 | G7: =IFERROR(F7/AVERAGE('Ventas Diarias'!$J:$J)-1,0)
A8: Jueves | B8: =$O$1-WEEKDAY($O$1,2)+4 | C8: =SUMIFS('Ventas Diarias'!$J:$J,'Ventas Diarias'!$A:$A,B8,'Ventas Diarias'!$B:$B,"La Cata LMF") | D8: =SUMIFS('Ventas Diarias'!$J:$J,'Ventas Diarias'!$A:$A,B8,'Ventas Diarias'!$B:$B,"La Cata DF") | E8: =SUMIFS('Ventas Diarias'!$J:$J,'Ventas Diarias'!$A:$A,B8,'Ventas Diarias'!$B:$B,"La Cata SJM") | F8: =C8+D8+E8 | G8: =IFERROR(F8/AVERAGE('Ventas Diarias'!$J:$J)-1,0)
A9: Viernes | B9: =$O$1-WEEKDAY($O$1,2)+5 | C9: =SUMIFS('Ventas Diarias'!$J:$J,'Ventas Diarias'!$A:$A,B9,'Ventas Diarias'!$B:$B,"La Cata LMF") | D9: =SUMIFS('Ventas Diarias'!$J:$J,'Ventas Diarias'!$A:$A,B9,'Ventas Diarias'!$B:$B,"La Cata DF") | E9: =SUMIFS('Ventas Diarias'!$J:$J,'Ventas Diarias'!$A:$A,B9,'Ventas Diarias'!$B:$B,"La Cata SJM") | F9: =C9+D9+E9 | G9: =IFERROR(F9/AVERAGE('Ventas Diarias'!$J:$J)-1,0)
A10: Sábado | B10: =$O$1-WEEKDAY($O$1,2)+6 | C10: =SUMIFS('Ventas Diarias'!$J:$J,'Ventas Diarias'!$A:$A,B10,'Ventas Diarias'!$B:$B,"La Cata LMF") | D10: =SUMIFS('Ventas Diarias'!$J:$J,'Ventas Diarias'!$A:$A,B10,'Ventas Diarias'!$B:$B,"La Cata DF") | E10: =SUMIFS('Ventas Diarias'!$J:$J,'Ventas Diarias'!$A:$A,B10,'Ventas Diarias'!$B:$B,"La Cata SJM") | F10: =C10+D10+E10 | G10: =IFERROR(F10/AVERAGE('Ventas Diarias'!$J:$J)-1,0)
A11: Domingo | B11: =$O$1-WEEKDAY($O$1,2)+7 | C11: =SUMIFS('Ventas Diarias'!$J:$J,'Ventas Diarias'!$A:$A,B11,'Ventas Diarias'!$B:$B,"La Cata LMF") | D11: =SUMIFS('Ventas Diarias'!$J:$J,'Ventas Diarias'!$A:$A,B11,'Ventas Diarias'!$B:$B,"La Cata DF") | E11: =SUMIFS('Ventas Diarias'!$J:$J,'Ventas Diarias'!$A:$A,B11,'Ventas Diarias'!$B:$B,"La Cata SJM") | F11: =C11+D11+E11 | G11: =IFERROR(F11/AVERAGE('Ventas Diarias'!$J:$J)-1,0)
A12: TOTAL SEMANA | C12: =SUM(C5:C11) | D12: =SUM(D5:D11) | E12: =SUM(E5:E11) | F12: =SUM(F5:F11) | G12: =IFERROR(F12/(AVERAGE('Ventas Diarias'!$J:$J)*7)-1,0)
A14: 📆 VENTAS MENSUALES POR TIENDA | Q14: Distribución Total 2026
A15: Mes | B15: La Cata LMF | C15: La Cata DF | D15: La Cata SJM | E15: TOTAL | F15: % LMF | G15: % DF | H15: % SJM | Q15: Tienda | R15: Total
A16: Enero 2026 | B16: =SUMIFS('Ventas Diarias'!$J:$J,'Ventas Diarias'!$A:$A,">="&46023,'Ventas Diarias'!$A:$A,"<="&46053,'Ventas Diarias'!$B:$B,"La Cata LMF") | C16: =SUMIFS('Ventas Diarias'!$J:$J,'Ventas Diarias'!$A:$A,">="&46023,'Ventas Diarias'!$A:$A,"<="&46053,'Ventas Diarias'!$B:$B,"La Cata DF") | D16: =SUMIFS('Ventas Diarias'!$J:$J,'Ventas Diarias'!$A:$A,">="&46023,'Ventas Diarias'!$A:$A,"<="&46053,'Ventas Diarias'!$B:$B,"La Cata SJM") | E16: =B16+C16+D16 | F16: =IFERROR(B16/E16,0) | G16: =IFERROR(C16/E16,0) | H16: =IFERROR(D16/E16,0) | Q16: La Cata LMF | R16: =B28
A17: Febrero 2026 | B17: =SUMIFS('Ventas Diarias'!$J:$J,'Ventas Diarias'!$A:$A,">="&46054,'Ventas Diarias'!$A:$A,"<="&46081,'Ventas Diarias'!$B:$B,"La Cata LMF") | C17: =SUMIFS('Ventas Diarias'!$J:$J,'Ventas Diarias'!$A:$A,">="&46054,'Ventas Diarias'!$A:$A,"<="&46081,'Ventas Diarias'!$B:$B,"La Cata DF") | D17: =SUMIFS('Ventas Diarias'!$J:$J,'Ventas Diarias'!$A:$A,">="&46054,'Ventas Diarias'!$A:$A,"<="&46081,'Ventas Diarias'!$B:$B,"La Cata SJM") | E17: =B17+C17+D17 | F17: =IFERROR(B17/E17,0) | G17: =IFERROR(C17/E17,0) | H17: =IFERROR(D17/E17,0) | Q17: La Cata DF | R17: =C28
A18: Marzo 2026 | B18: =SUMIFS('Ventas Diarias'!$J:$J,'Ventas Diarias'!$A:$A,">="&46082,'Ventas Diarias'!$A:$A,"<="&46112,'Ventas Diarias'!$B:$B,"La Cata LMF") | C18: =SUMIFS('Ventas Diarias'!$J:$J,'Ventas Diarias'!$A:$A,">="&46082,'Ventas Diarias'!$A:$A,"<="&46112,'Ventas Diarias'!$B:$B,"La Cata DF") | D18: =SUMIFS('Ventas Diarias'!$J:$J,'Ventas Diarias'!$A:$A,">="&46082,'Ventas Diarias'!$A:$A,"<="&46112,'Ventas Diarias'!$B:$B,"La Cata SJM") | E18: =B18+C18+D18 | F18: =IFERROR(B18/E18,0) | G18: =IFERROR(C18/E18,0) | H18: =IFERROR(D18/E18,0) | Q18: La Cata SJM | R18: =D28
A19: Abril 2026 | B19: =SUMIFS('Ventas Diarias'!$J:$J,'Ventas Diarias'!$A:$A,">="&46113,'Ventas Diarias'!$A:$A,"<="&46142,'Ventas Diarias'!$B:$B,"La Cata LMF") | C19: =SUMIFS('Ventas Diarias'!$J:$J,'Ventas Diarias'!$A:$A,">="&46113,'Ventas Diarias'!$A:$A,"<="&46142,'Ventas Diarias'!$B:$B,"La Cata DF") | D19: =SUMIFS('Ventas Diarias'!$J:$J,'Ventas Diarias'!$A:$A,">="&46113,'Ventas Diarias'!$A:$A,"<="&46142,'Ventas Diarias'!$B:$B,"La Cata SJM") | E19: =B19+C19+D19 | F19: =IFERROR(B19/E19,0) | G19: =IFERROR(C19/E19,0) | H19: =IFERROR(D19/E19,0)
A20: Mayo 2026 | B20: =SUMIFS('Ventas Diarias'!$J:$J,'Ventas Diarias'!$A:$A,">="&46143,'Ventas Diarias'!$A:$A,"<="&46173,'Ventas Diarias'!$B:$B,"La Cata LMF") | C20: =SUMIFS('Ventas Diarias'!$J:$J,'Ventas Diarias'!$A:$A,">="&46143,'Ventas Diarias'!$A:$A,"<="&46173,'Ventas Diarias'!$B:$B,"La Cata DF") | D20: =SUMIFS('Ventas Diarias'!$J:$J,'Ventas Diarias'!$A:$A,">="&46143,'Ventas Diarias'!$A:$A,"<="&46173,'Ventas Diarias'!$B:$B,"La Cata SJM") | E20: =B20+C20+D20 | F20: =IFERROR(B20/E20,0) | G20: =IFERROR(C20/E20,0) | H20: =IFERROR(D20/E20,0) | Q20: Métodos de Pago
A21: Junio 2026 | B21: =SUMIFS('Ventas Diarias'!$J:$J,'Ventas Diarias'!$A:$A,">="&46174,'Ventas Diarias'!$A:$A,"<="&46203,'Ventas Diarias'!$B:$B,"La Cata LMF") | C21: =SUMIFS('Ventas Diarias'!$J:$J,'Ventas Diarias'!$A:$A,">="&46174,'Ventas Diarias'!$A:$A,"<="&46203,'Ventas Diarias'!$B:$B,"La Cata DF") | D21: =SUMIFS('Ventas Diarias'!$J:$J,'Ventas Diarias'!$A:$A,">="&46174,'Ventas Diarias'!$A:$A,"<="&46203,'Ventas Diarias'!$B:$B,"La Cata SJM") | E21: =B21+C21+D21 | F21: =IFERROR(B21/E21,0) | G21: =IFERROR(C21/E21,0) | H21: =IFERROR(D21/E21,0) | Q21: Tienda | R21: Efectivo | S21: Tarjeta Neta | T21: Transferencias
A22: Julio 2026 | B22: =SUMIFS('Ventas Diarias'!$J:$J,'Ventas Diarias'!$A:$A,">="&46204,'Ventas Diarias'!$A:$A,"<="&46234,'Ventas Diarias'!$B:$B,"La Cata LMF") | C22: =SUMIFS('Ventas Diarias'!$J:$J,'Ventas Diarias'!$A:$A,">="&46204,'Ventas Diarias'!$A:$A,"<="&46234,'Ventas Diarias'!$B:$B,"La Cata DF") | D22: =SUMIFS('Ventas Diarias'!$J:$J,'Ventas Diarias'!$A:$A,">="&46204,'Ventas Diarias'!$A:$A,"<="&46234,'Ventas Diarias'!$B:$B,"La Cata SJM") | E22: =B22+C22+D22 | F22: =IFERROR(B22/E22,0) | G22: =IFERROR(C22/E22,0) | H22: =IFERROR(D22/E22,0)
A23: Agosto 2026 | B23: =SUMIFS('Ventas Diarias'!$J:$J,'Ventas Diarias'!$A:$A,">="&46235,'Ventas Diarias'!$A:$A,"<="&46265,'Ventas Diarias'!$B:$B,"La Cata LMF") | C23: =SUMIFS('Ventas Diarias'!$J:$J,'Ventas Diarias'!$A:$A,">="&46235,'Ventas Diarias'!$A:$A,"<="&46265,'Ventas Diarias'!$B:$B,"La Cata DF") | D23: =SUMIFS('Ventas Diarias'!$J:$J,'Ventas Diarias'!$A:$A,">="&46235,'Ventas Diarias'!$A:$A,"<="&46265,'Ventas Diarias'!$B:$B,"La Cata SJM") | E23: =B23+C23+D23 | F23: =IFERROR(B23/E23,0) | G23: =IFERROR(C23/E23,0) | H23: =IFERROR(D23/E23,0)
A24: Septiembre 2026 | B24: =SUMIFS('Ventas Diarias'!$J:$J,'Ventas Diarias'!$A:$A,">="&46266,'Ventas Diarias'!$A:$A,"<="&46295,'Ventas Diarias'!$B:$B,"La Cata LMF") | C24: =SUMIFS('Ventas Diarias'!$J:$J,'Ventas Diarias'!$A:$A,">="&46266,'Ventas Diarias'!$A:$A,"<="&46295,'Ventas Diarias'!$B:$B,"La Cata DF") | D24: =SUMIFS('Ventas Diarias'!$J:$J,'Ventas Diarias'!$A:$A,">="&46266,'Ventas Diarias'!$A:$A,"<="&46295,'Ventas Diarias'!$B:$B,"La Cata SJM") | E24: =B24+C24+D24 | F24: =IFERROR(B24/E24,0) | G24: =IFERROR(C24/E24,0) | H24: =IFERROR(D24/E24,0)
A25: Octubre 2026 | B25: =SUMIFS('Ventas Diarias'!$J:$J,'Ventas Diarias'!$A:$A,">="&46296,'Ventas Diarias'!$A:$A,"<="&46326,'Ventas Diarias'!$B:$B,"La Cata LMF") | C25: =SUMIFS('Ventas Diarias'!$J:$J,'Ventas Diarias'!$A:$A,">="&46296,'Ventas Diarias'!$A:$A,"<="&46326,'Ventas Diarias'!$B:$B,"La Cata DF") | D25: =SUMIFS('Ventas Diarias'!$J:$J,'Ventas Diarias'!$A:$A,">="&46296,'Ventas Diarias'!$A:$A,"<="&46326,'Ventas Diarias'!$B:$B,"La Cata SJM") | E25: =B25+C25+D25 | F25: =IFERROR(B25/E25,0) | G25: =IFERROR(C25/E25,0) | H25: =IFERROR(D25/E25,0)
A26: Noviembre 2026 | B26: =SUMIFS('Ventas Diarias'!$J:$J,'Ventas Diarias'!$A:$A,">="&46327,'Ventas Diarias'!$A:$A,"<="&46356,'Ventas Diarias'!$B:$B,"La Cata LMF") | C26: =SUMIFS('Ventas Diarias'!$J:$J,'Ventas Diarias'!$A:$A,">="&46327,'Ventas Diarias'!$A:$A,"<="&46356,'Ventas Diarias'!$B:$B,"La Cata DF") | D26: =SUMIFS('Ventas Diarias'!$J:$J,'Ventas Diarias'!$A:$A,">="&46327,'Ventas Diarias'!$A:$A,"<="&46356,'Ventas Diarias'!$B:$B,"La Cata SJM") | E26: =B26+C26+D26 | F26: =IFERROR(B26/E26,0) | G26: =IFERROR(C26/E26,0) | H26: =IFERROR(D26/E26,0)
A27: Diciembre 2026 | B27: =SUMIFS('Ventas Diarias'!$J:$J,'Ventas Diarias'!$A:$A,">="&46357,'Ventas Diarias'!$A:$A,"<="&46387,'Ventas Diarias'!$B:$B,"La Cata LMF") | C27: =SUMIFS('Ventas Diarias'!$J:$J,'Ventas Diarias'!$A:$A,">="&46357,'Ventas Diarias'!$A:$A,"<="&46387,'Ventas Diarias'!$B:$B,"La Cata DF") | D27: =SUMIFS('Ventas Diarias'!$J:$J,'Ventas Diarias'!$A:$A,">="&46357,'Ventas Diarias'!$A:$A,"<="&46387,'Ventas Diarias'!$B:$B,"La Cata SJM") | E27: =B27+C27+D27 | F27: =IFERROR(B27/E27,0) | G27: =IFERROR(C27/E27,0) | H27: =IFERROR(D27/E27,0)
A28: TOTAL 2026 | B28: =SUM(B16:B27) | C28: =SUM(C16:C27) | D28: =SUM(D16:D27) | E28: =SUM(E16:E27) | F28: =IFERROR(B28/E28,0) | G28: =IFERROR(C28/E28,0) | H28: =IFERROR(D28/E28,0) | Q28: LMF | R28: =B47 | S28: =C47-D47 | T28: =E47
A29: Crecimiento Mensual | B29: =IFERROR((B21-B20)/B20,"N/A") | C29: =IFERROR((C21-C20)/C20,"N/A") | D29: =IFERROR((D21-D20)/D20,"N/A") | E29: =IFERROR((E21-E20)/E20,"N/A") | F29: =IFERROR(B29/E29,0) | G29: =IFERROR(C29/E29,0) | H29: =IFERROR(D29/E29,0) | Q29: DF | R29: =B48 | S29: =C48-D48 | T29: =E48
A30: 📈 INDICADORES CLAVE (KPIs) | Q30: SJM | R30: =B49 | S30: =C49-D49 | T30: =E49
A31: Promedio Diario LMF: | B31: =AVERAGEIF('Ventas Diarias'!$B:$B,"La Cata LMF",'Ventas Diarias'!$J:$J) | C31: Promedio Diario DF: | D31: =AVERAGEIF('Ventas Diarias'!$B:$B,"La Cata DF",'Ventas Diarias'!$J:$J) | E31: Promedio Diario SJM: | F31: =AVERAGEIF('Ventas Diarias'!$B:$B,"La Cata SJM",'Ventas Diarias'!$J:$J)
A32: Mejor Día LMF: | B32: =_xlfn.MAXIFS('Ventas Diarias'!$J:$J,'Ventas Diarias'!$B:$B,"La Cata LMF") | C32: Mejor Día DF: | D32: =_xlfn.MAXIFS('Ventas Diarias'!$J:$J,'Ventas Diarias'!$B:$B,"La Cata DF") | E32: Mejor Día SJM: | F32: =_xlfn.MAXIFS('Ventas Diarias'!$J:$J,'Ventas Diarias'!$B:$B,"La Cata SJM")
L33: 💵 CONTROL DE DEPÓSITOS VS EFECTIVO VENDIDO
A34: 📊 VENTAS PROMEDIO POR DÍA DE LA SEMANA | L34: Ciclo: Domingo a Sábado | Depósito: Lunes siguiente | Tolerancia: ±RD$500
A35: Día | B35: La Cata LMF | C35: La Cata DF | D35: La Cata SJM | E35: Promedio Total
A36: Lunes | B36: {=IFERROR(SUMPRODUCT(('Ventas Diarias'!$B$2:$B$500="La Cata LMF")*(WEEKDAY('Ventas Diarias'!$A$2:$A$500,2)=1)*('Ventas Diarias'!$J$2:$J$500))/SUMPRODUCT(('Ventas Diarias'!$B$2:$B$500="La Cata LMF")*(WEEKDAY('Ventas Diarias'!$A$2:$A$500,2)=1)*('Ventas Diarias'!$J$2:$J$500<>0)),0)} | C36: {=IFERROR(SUMPRODUCT(('Ventas Diarias'!$B$2:$B$500="La Cata DF")*(WEEKDAY('Ventas Diarias'!$A$2:$A$500,2)=1)*('Ventas Diarias'!$J$2:$J$500))/SUMPRODUCT(('Ventas Diarias'!$B$2:$B$500="La Cata DF")*(WEEKDAY('Ventas Diarias'!$A$2:$A$500,2)=1)*('Ventas Diarias'!$J$2:$J$500<>0)),0)} | D36: {=IFERROR(SUMPRODUCT(('Ventas Diarias'!$B$2:$B$500="La Cata SJM")*(WEEKDAY('Ventas Diarias'!$A$2:$A$500,2)=1)*('Ventas Diarias'!$J$2:$J$500))/SUMPRODUCT(('Ventas Diarias'!$B$2:$B$500="La Cata SJM")*(WEEKDAY('Ventas Diarias'!$A$2:$A$500,2)=1)*('Ventas Diarias'!$J$2:$J$500<>0)),0)} | E36: =IFERROR(AVERAGE(B36:D36),0) | L36: 🏪 LA CATA LMF
A37: Martes | B37: {=IFERROR(SUMPRODUCT(('Ventas Diarias'!$B$2:$B$500="La Cata LMF")*(WEEKDAY('Ventas Diarias'!$A$2:$A$500,2)=2)*('Ventas Diarias'!$J$2:$J$500))/SUMPRODUCT(('Ventas Diarias'!$B$2:$B$500="La Cata LMF")*(WEEKDAY('Ventas Diarias'!$A$2:$A$500,2)=2)*('Ventas Diarias'!$J$2:$J$500<>0)),0)} | C37: {=IFERROR(SUMPRODUCT(('Ventas Diarias'!$B$2:$B$500="La Cata DF")*(WEEKDAY('Ventas Diarias'!$A$2:$A$500,2)=2)*('Ventas Diarias'!$J$2:$J$500))/SUMPRODUCT(('Ventas Diarias'!$B$2:$B$500="La Cata DF")*(WEEKDAY('Ventas Diarias'!$A$2:$A$500,2)=2)*('Ventas Diarias'!$J$2:$J$500<>0)),0)} | D37: {=IFERROR(SUMPRODUCT(('Ventas Diarias'!$B$2:$B$500="La Cata SJM")*(WEEKDAY('Ventas Diarias'!$A$2:$A$500,2)=2)*('Ventas Diarias'!$J$2:$J$500))/SUMPRODUCT(('Ventas Diarias'!$B$2:$B$500="La Cata SJM")*(WEEKDAY('Ventas Diarias'!$A$2:$A$500,2)=2)*('Ventas Diarias'!$J$2:$J$500<>0)),0)} | E37: =IFERROR(AVERAGE(B37:D37),0) | L37: Semana | M37: Inicio | N37: Fin | O37: Efectivo Vendido | P37: Depósito | Q37: Diferencia | R37: % Var | S37: Estado
